<?xml version="1.0"?>
<robot name="hek_4L_1.0">

  <link name="base">
    <visual>
      <origin xyz="0 0 0" rpy="0 0 0"/>
      <geometry>
        <mesh filename="package://hekateros_desc/stl/hek_4L_1.0/base.stl" 
              scale="0.001 0.001 0.001"
        />
      </geometry>
      <material name="black">
        <color rgba="0 0 0 0.7"/>
      </material>
    </visual>
  </link>

  <link name="upper_arm">
    <visual>
      <origin xyz="0.0 0.02 0.18" rpy="1.5705 1.5705 -1.5705"/>
      <geometry>
        <mesh filename="package://hekateros_desc/stl/hek_4L_1.0/upper_arm.stl" 
              scale="0.001 0.001 0.001"
        />
      </geometry>
      <material name="red">
        <color rgba="0.8 0 0 0.9"/>
      </material>
    </visual>
  </link>

  <link name="forearm">
    <visual>
      <origin xyz="0. 0.0 0.03" rpy="03.1415 0 1.5705"/>
      <geometry>
        <mesh filename="package://hekateros_desc/stl/hek_4L_1.0/forearm.stl" 
              scale="0.001 0.001 0.001"
        />
      </geometry>
      <material name="red">
        <color rgba="0.8 0 0 0.9"/>
      </material>
    </visual>
  </link>

  <link name="wrist_link">
    <visual>
      <origin xyz="0.0 0 -0.017" rpy="0 0 0"/>
      <geometry>
        <mesh filename="package://hekateros_desc/stl/hek_4L_1.0/wrist.stl" 
              scale="0.001 0.001 0.001"
        />
      </geometry>
      <material name="black">
        <color rgba="0 0 0 0.9"/>
      </material>
    </visual>
  </link>

  <link name="tool_zero">
    <visual>
      <origin xyz="0 0.06 0" rpy="3.14159 0 0"/>
      <geometry>
        <mesh filename="package://hekateros_desc/stl/hek_4L_1.0/tool_zero.stl" 
              scale="0.001 0.001 0.001"
        />
      </geometry>
      <material name="red">
        <color rgba="0.8 0 0 0.9"/>
      </material>
    </visual>
  </link>

  <joint name="shoulder" type="revolute">
    <origin xyz="0.23 -0.04 0.11" rpy="0 0 0"/>
    <parent link="base"/>
    <child link="upper_arm"/>

    <limit effort="30" velocity="1.0" lower="-1.57" upper="1.57" />
  </joint>

  <joint name="elbow" type="revolute">
    <origin xyz="-0.015 0.0 0.405" rpy="0 0 0"/>
    <parent link="upper_arm"/>
    <child link="forearm"/>

    <limit effort="30" velocity="1.0" lower="-1.9" upper="1.9" />
  </joint>

  <joint name="wrist_pitch" type="revolute">
    <origin xyz="-0.005 0 0.40" rpy="0 0 0"/>
    <parent link="forearm"/>
    <child link="wrist_link"/>

    <limit effort="30" velocity="1.0" lower="-1.57" upper="1.57" />
  </joint>

  <joint name="wrist_rot" type="continuous">
    <origin xyz="0 0 0.025" rpy="0 0 0"/>
    <axis xyz="0 0 1"/>
    <parent link="wrist_link"/>
    <child link="tool_zero"/>

    <limit effort="30" velocity="1.0" lower="-1.57" upper="1.57" />
  </joint>

  <!-- EEF -->
  <link name="gear_assembly">
    <visual>
      <origin xyz="0 0 0.02" rpy="0 -1.575 3.14159"/>
      <geometry>
        <mesh filename="package://hekateros_desc/stl/graboid/gear_assembly.stl" 
              scale="0.001 0.001 0.001"
        />
      </geometry>
      <material name="black">
        <color rgba="0 0 0 0.7"/>
      </material>
    </visual>
  </link>

  <link name="finger_R">
    <visual>
      <origin xyz="0 0 0" rpy="0 0 -1.7"/>
      <geometry>
        <mesh filename="package://hekateros_desc/stl/graboid/finger_R.stl" 
              scale="0.001 0.001 0.001"
        />
      </geometry>
      <material name="red">
        <color rgba="0.8 0 0 0.9"/>
      </material>
    </visual>
  </link>

  <link name="finger_L">
    <visual>
      <origin xyz="0 0 0" rpy="0 -3.141 -1.575"/>
      <geometry>
        <mesh filename="package://hekateros_desc/stl/graboid/finger_L.stl" 
              scale="0.001 0.001 0.001"
        />
      </geometry>
      <material name="red">
        <color rgba="0.8 0 0 0.9"/>
      </material>
    </visual>
  </link>

  <joint name="grip" type="revolute">
    <axis xyz="0 0 1"/>
    <origin xyz="0.005 -0.04 0.03" rpy="0 -1.575 0"/>
    <parent link="gear_assembly"/>
    <child link="finger_R"/>

    <limit effort="30" velocity="1.0" lower="-1.57" upper="0" />
  </joint>

  <joint name="grip_mimic" type="revolute">
    <axis xyz="0 0 1"/>
    <origin xyz="0.0 0.0 0.03" rpy="0 -1.575 0"/>
    <parent link="gear_assembly"/>
    <child link="finger_L"/>
    
    <limit effort="30" velocity="1.0" lower="-1.57" upper="1.57" />
    <mimic joint="grip" multiplier="1"/>
  </joint>


  <joint name="eef_connect" type="fixed">
    <origin xyz="-0.02 -0.025 0.03" rpy="0 0 1.575"/>
    <parent link="tool_zero"/>
    <child link="gear_assembly"/>
  </joint>

</robot>

